Workbook

Sheet PERSONAL ACTIVO
B3: FECHA DE MASTER
AB4: DATOS ADICIONALES A LLENAR
A5: N° | B5: SEDE | C5: CLÍNICA | D5: CODIGO | E5: FECHA DE ATENCION (dd/mm/yyyy) | F5: TIPO DOCUMENTO | G5: NRO DOCUMENTO | H5: APELLIDO PATERNO | I5: APELLIDO MATERNO | J5: NOMBRES | K5: APELLIDOS Y NOMBRES COMPLETOS (NO TOCAR ESTA FILA) | L5: SEXO | M5: FECHA NACIMIENTO (dd/mm/aaaa) | N5: CELULAR | O5: CORREO | P5: COMPAÑÍA | Q5: UNIDAD | R5: EMPRESA CONTRATISTA | S5: RUC (Empresa Contratista) | T5: ZONA DE TRABAJO | U5: AREA DE TRABAJO | V5: PUESTO | W5: UBICACIÓN | X5: DIRECCION | Y5: DISTRITO | Z5: PROVINCIA | AA5: DEPARTAMENTO | AB5: EDAD | AC5: DESTINO | AD5: LUGAR DE EMBARQUE (SAN ANDRES, BUENOS AIRES, CEO, CHILCAS OESTE) | AE5: STATUS P1, P2, P3, P4, INMUNE | AF5: FECHA DE INGRESO | AG5: TIEMPO EN UNIDAD | AJ5: FECHA DE BAJA | AK5: OBSERVACIONES
A6: STAFF | AG6: AÑOS | AH6: MESES | AI6: DÍAS
A7: 3 | B7: SAN ANDRES | C7: CENTRO MEDICO | D7: GC0000003 | F7: DNI | G7: 73067972 | H7: ZAMORA | I7: LA TORRE | J7: EDUARDO HUMBERTO | K7: =CONCATENATE(H7," ",I7," ",J7) -> ZAMORA LA TORRE EDUARDO HUMBERTO | L7: MASCULINO | M7: 34954 | N7: 961792237 | O7: eduardo.zamora@grupocredco.com | P7: MINERA AURIFERA RETAMAS S.A. | Q7: SAN ANDRES | R7: GRUPO CREDCO EMPRESA DE INGENIERIA, ARQUITECTURA Y CONSTRUCCION S.A.C. | S7: 20601242657 | T7: SUPERFICIE | U7: PROYECTOS E INFRAESTUCTURA | V7: INGENIERO RESIDENTE | W7: CAJAMARCA | X7: JR. BOLIVAR 341 | Y7: CAJAMARCA | Z7: CAJAMARCA | AA7: CAJAMARCA | AB7: =DATEDIF(M7,TODAY(),"y")&" AÑOS" -> 30 AÑOS | AC7: HUAMACHUCO | AD7: SAN ANDRES | AF7: 44258 | AG7: =DATEDIF(AF7,TODAY(),"Y") -> 4 | AH7: =DATEDIF(AF7,TODAY(),"YM") -> 10 | AI7: =DATEDIF(AF7,TODAY(),"MD") -> 27
A8: 199 | B8: SAN ANDRES | C8: CENTRO MEDICO | D8: GC0000199 | F8: DNI | G8: 71246409 | H8: PESCORÁN | I8: CAMPOS | J8: MANUEL DAVID | K8: =CONCATENATE(H8," ",I8," ",J8) -> PESCORÁN CAMPOS MANUEL DAVID | L8: MASCULINO | M8: 35268 | N8: 963308915 | O8: manuel.pescoran@grupocredco.com | P8: MINERA AURIFERA RETAMAS S.A. | Q8: SAN ANDRES | R8: GRUPO CREDCO EMPRESA DE INGENIERIA, ARQUITECTURA Y CONSTRUCCION S.A.C. | S8: 20601242657 | T8: SUPERFICIE | U8: PROYECTOS E INFRAESTUCTURA | V8: SUPERVISOR DE OBRAS CIVILES | W8: LA LIBERTAD | X8: CALLE MAGNESIO 380 | Y8: TRUJILLO | Z8: TRUJILLO | AA8: LA LIBERTAD | AB8: =DATEDIF(M8,TODAY(),"y")&" AÑOS" -> 29 AÑOS | AC8: TRUJILLO | AD8: SAN ANDRES | AF8: 45264 | AG8: =DATEDIF(AF8,TODAY(),"Y") -> 2 | AH8: =DATEDIF(AF8,TODAY(),"YM") -> 1 | AI8: =DATEDIF(AF8,TODAY(),"MD") -> 26
A9: 207 | B9: SAN ANDRES | C9: CENTRO MEDICO | D9: GC0000207 | F9: DNI | G9: 72096059 | H9: HUAYLLA | I9: LARREA | J9: ALVARO JOSÉ | K9: =CONCATENATE(H9," ",I9," ",J9) -> HUAYLLA LARREA ALVARO JOSÉ | L9: MASCULINO | M9: 34823 | N9: 918564131 | O9: alvaro.huaylla@grupocredco.com | P9: MINERA AURIFERA RETAMAS S.A. | Q9: SAN ANDRES | R9: GRUPO CREDCO EMPRESA DE INGENIERIA, ARQUITECTURA Y CONSTRUCCION S.A.C. | S9: 20601242657 | T9: SUPERFICIE | U9: PROYECTOS E INFRAESTUCTURA | V9: SUPERVISOR DE SEGURIDAD | W9: CAJAMARCA | X9: JR. GUILLERO URRELO 1623 | Y9: CAJAMARCA | Z9: CAJAMARCA | AA9: CAJAMARCA | AB9: =DATEDIF(M9,TODAY(),"y")&" AÑOS" -> 30 AÑOS | AC9: TRUJILLO | AD9: SAN ANDRES | AF9: 45225 | AG9: =DATEDIF(AF9,TODAY(),"Y") -> 2 | AH9: =DATEDIF(AF9,TODAY(),"YM") -> 3 | AI9: =DATEDIF(AF9,TODAY(),"MD") -> 4
A10: 263 | B10: SAN ANDRES | C10: CENTRO MEDICO | D10: GC0000266 | F10: DNI | G10: 75502801 | H10: ODAR | I10: RUIZ | J10: MOISES | K10: =CONCATENATE(H10," ",I10," ",J10) -> ODAR RUIZ MOISES | L10: MASCULINO | M10: 36981 | N10: 949523727 | O10: odarrmoises@gmail.com | P10: MINERA AURIFERA RETAMAS S.A. | Q10: SAN ANDRES | R10: GRUPO CREDCO EMPRESA DE INGENIERIA, ARQUITECTURA Y CONSTRUCCION S.A.C. | S10: 20601242658 | T10: SUPERFICIE | U10: PROYECTOS E INFRAESTUCTURA | V10: SUPERVISOR DE SEGURIDAD | W10: LA LIBERTAD | X10: CALLE JOSE PINELO 429 URB RAZURI | Y10: TRUJILLO | Z10: TRUJILLO | AA10: LA LIBERTAD | AB10: =DATEDIF(M10,TODAY(),"y")&" AÑOS" -> 24 AÑOS | AC10: TRUJILLO | AD10: TRUJILLO | AF10: 45932 | AG10: =DATEDIF(AF10,TODAY(),"Y") -> 0 | AH10: =DATEDIF(AF10,TODAY(),"YM") -> 3 | AI10: =DATEDIF(AF10,TODAY(),"MD") -> 28
A11: 176 | B11: SAN ANDRES | C11: CENTRO MEDICO | D11: GC0000295 | F11: DNI | G11: 72395332 | H11: MALCA | I11: ROQUE | J11: KEVIN ARNOLD | K11: =CONCATENATE(H11," ",I11," ",J11) -> MALCA ROQUE KEVIN ARNOLD | L11: MASCULINO | M11: 33811 | N11: 940128943 | O11: malca_28@hotmail.com | P11: MINERA AURIFERA RETAMAS S.A. | Q11: SAN ANDRES | R11: GRUPO CREDCO EMPRESA DE INGENIERIA, ARQUITECTURA Y CONSTRUCCION S.A.C. | S11: 20601242657 | T11: SUPERFICIE | U11: PROYECTOS E INFRAESTUCTURA | V11: ASISTENTE ADMINISTRATIVO | W11: CAJAMARCA | X11: CALLE LAS CUCARDAS 255 | Y11: CAJAMRCA | Z11: CAJAMARCA | AA11: CAJAMRCA | AB11: =DATEDIF(M11,TODAY(),"y")&" AÑOS" -> 33 AÑOS | AC11: TRUJILLO | AD11: SAN ANDRES | AF11: 46020 | AG11: =DATEDIF(AF11,TODAY(),"Y") -> 0 | AH11: =DATEDIF(AF11,TODAY(),"YM") -> 1 | AI11: =DATEDIF(AF11,TODAY(),"MD") -> 1
A12: CONDUCTORES
A13: 224 | B13: SAN ANDRES | C13: CENTRO MEDICO | D13: GC0000224 | F13: DNI | G13: 46581212 | H13: CHUNQUE | I13: PINEDO | J13: ALEXANDER | K13: =CONCATENATE(H13," ",I13," ",J13) -> CHUNQUE PINEDO ALEXANDER | L13: MASCULINO | M13: 32929 | N13: 993157218 | O13: Chunque_2012@hotmailcom | P13: MINERA AURIFERA RETAMAS S.A. | Q13: SAN ANDRES | R13: GRUPO CREDCO EMPRESA DE INGENIERIA, ARQUITECTURA Y CONSTRUCCION S.A.C. | S13: 20601242657 | T13: SUPERFICIE | U13: PROYECTOS E INFRAESTUCTURA | V13: CHOFER | W13: CAJAMARCA | X13: JR ALFONZO UGARTE E 2 | Y13: CAJAMARCA | Z13: CAJAMARCA | AA13: CAJAMARCA | AB13: =DATEDIF(M13,TODAY(),"y")&" AÑOS" -> 35 AÑOS | AC13: HUAMACHUCO | AD13: SAN ANDRES | AF13: 45547 | AG13: =DATEDIF(AF13,TODAY(),"Y") -> 1 | AH13: =DATEDIF(AF13,TODAY(),"YM") -> 4 | AI13: =DATEDIF(AF13,TODAY(),"MD") -> 18
A14: PERSONAL DE PISO
A15: 16 | B15: SAN ANDRES | C15: CENTRO MEDICO | D15: GC0000016 | F15: DNI | G15: 73036170 | H15: CARRANZA | I15: MISAHUAMAN | J15: RONAL MIKI | K15: =CONCATENATE(H15," ",I15," ",J15) -> CARRANZA MISAHUAMAN RONAL MIKI | L15: MASCULINO | M15: 34312 | N15: 913852748 | O15: ronalcarranza1994@outlook.com | P15: MINERA AURIFERA RETAMAS S.A. | Q15: SAN ANDRES | R15: GRUPO CREDCO EMPRESA DE INGENIERIA, ARQUITECTURA Y CONSTRUCCION S.A.C. | S15: 20601242657 | T15: SUPERFICIE | U15: PROYECTOS E INFRAESTUCTURA | V15: CAPATAZ | W15: CAJAMARCA | X15: Jr Jose Quiñones 707 | Y15: CAJAMARCA | Z15: CAJAMARCA | AA15: CAJAMARCA | AB15: =DATEDIF(M15,TODAY(),"y")&" AÑOS" -> 32 AÑOS | AC15: HUAMACHUCO | AD15: SAN ANDRES | AF15: 44280 | AG15: =DATEDIF(AF15,TODAY(),"Y") -> 4 | AH15: =DATEDIF(AF15,TODAY(),"YM") -> 10 | AI15: =DATEDIF(AF15,TODAY(),"MD") -> 5
A16: 71 | B16: SAN ANDRES | C16: CENTRO MEDICO | D16: GC0000071 | F16: DNI | G16: 26731702 | H16: TERAN | I16: REVILLA | J16: NORBERTO | K16: =CONCATENATE(H16," ",I16," ",J16) -> TERAN REVILLA NORBERTO | L16: MASCULINO | M16: 28282 | N16: 951354747 | O16: n06teran@gmail.com | P16: MINERA AURIFERA RETAMAS S.A. | Q16: SAN ANDRES | R16: GRUPO CREDCO EMPRESA DE INGENIERIA, ARQUITECTURA Y CONSTRUCCION S.A.C. | S16: 20601242657 | T16: SUPERFICIE | U16: PROYECTOS E INFRAESTUCTURA | V16: CAPATAZ | W16: CAJAMARCA | X16: Jr. Angamos 646 | Y16: CAJAMARCA | Z16: CAJAMARCA | AA16: CAJAMARCA | AB16: =DATEDIF(M16,TODAY(),"y")&" AÑOS" -> 48 AÑOS | AC16: HUAMACHUCO | AD16: SAN ANDRES | AF16: 44406 | AG16: =DATEDIF(AF16,TODAY(),"Y") -> 4 | AH16: =DATEDIF(AF16,TODAY(),"YM") -> 6 | AI16: =DATEDIF(AF16,TODAY(),"MD") -> 1
A17: 216 | B17: SAN ANDRES | C17: CENTRO MEDICO | D17: GC0000216 | E17: 45784 | F17: DNI | G17: 71002403 | H17: ANTICONA | I17: ANTICONA | J17: HEBER EFRAIN | K17: =CONCATENATE(H17," ",I17," ",J17) -> ANTICONA ANTICONA HEBER EFRAIN | L17: MASCULINO | M17: 37361 | N17: 965451507 | O17: everanticona159@gmail.com | P17: MINERA AURIFERA RETAMAS S.A. | Q17: SAN ANDRES | R17: GRUPO CREDCO EMPRESA DE INGENIERIA, ARQUITECTURA Y CONSTRUCCION S.A.C. | S17: 20601242657 | T17: SUPERFICIE | U17: PROYECTOS E INFRAESTUCTURA | V17: OPERARIO CIVIL | W17: HUAMACHUCO | X17: CASERIO LAGUNA SAUSACOCHA | Y17: HUAMACHUCO | Z17: SANCHEZ CARRION | AA17: LA LIBERTAD | AB17: =DATEDIF(M17,TODAY(),"y")&" AÑOS" -> 23 AÑOS | AC17: HUAMACHUCO | AD17: SAN ANDRES | AF17: 45383 | AG17: =DATEDIF(AF17,TODAY(),"Y") -> 1 | AH17: =DATEDIF(AF17,TODAY(),"YM") -> 9 | AI17: =DATEDIF(AF17,TODAY(),"MD") -> 29
A18: 28 | B18: SAN ANDRES | C18: CENTRO MEDICO | D18: GC0000028 | F18: DNI | G18: 70199652 | H18: CAHUANA | I18: CHUQUIMANGO | J18: EDILBERTO | K18: =CONCATENATE(H18," ",I18," ",J18) -> CAHUANA CHUQUIMANGO EDILBERTO | L18: MASCULINO | M18: 35464 | N18: 962744106 | O18: edicahuanachuqimango@gmail.com | P18: MINERA AURIFERA RETAMAS S.A. | Q18: SAN ANDRES | R18: GRUPO CREDCO EMPRESA DE INGENIERIA, ARQUITECTURA Y CONSTRUCCION S.A.C. | S18: 20601242657 | T18: SUPERFICIE | U18: PROYECTOS E INFRAESTUCTURA | V18: OPERARIO CIVIL | W18: CAJAMARCA | X18: Av. Miguel de Cervantes 249 | Y18: CAJAMARCA | Z18: CAJAMARCA | AA18: CAJAMARCA | AB18: =DATEDIF(M18,TODAY(),"y")&" AÑOS" -> 28 AÑOS | AC18: HUAMACHUCO | AD18: SAN ANDRES | AF18: 44288 | AG18: =DATEDIF(AF18,TODAY(),"Y") -> 4 | AH18: =DATEDIF(AF18,TODAY(),"YM") -> 9 | AI18: =DATEDIF(AF18,TODAY(),"MD") -> 28
A19: 5 | B19: SAN ANDRES | C19: CENTRO MEDICO | D19: GC0000005 | F19: DNI | G19: 47239686 | H19: MISAHUAMAN | I19: BARDALES | J19: FRANKLIN | K19: =CONCATENATE(H19," ",I19," ",J19) -> MISAHUAMAN BARDALES FRANKLIN | L19: MASCULINO | M19: 33474 | N19: 973455348 | O19: Franklinmisahuamanbardales24@gmail.com | P19: MINERA AURIFERA RETAMAS S.A. | Q19: SAN ANDRES | R19: GRUPO CREDCO EMPRESA DE INGENIERIA, ARQUITECTURA Y CONSTRUCCION S.A.C. | S19: 20601242657 | T19: SUPERFICIE | U19: PROYECTOS E INFRAESTUCTURA | V19: OPERARIO CIVIL | W19: CAJAMARCA | X19: CASERIO CHIGDEN-SAN JUAN | Y19: CAJAMARCA | Z19: CAJAMARCA | AA19: CAJAMARCA | AB19: =DATEDIF(M19,TODAY(),"y")&" AÑOS" -> 34 AÑOS | AC19: HUAMACHUCO | AD19: SAN ANDRES | AF19: 44260 | AG19: =DATEDIF(AF19,TODAY(),"Y") -> 4 | AH19: =DATEDIF(AF19,TODAY(),"YM") -> 10 | AI19: =DATEDIF(AF19,TODAY(),"MD") -> 25
A20: 231 | B20: SAN ANDRES | C20: CENTRO MEDICO | D20: GC0000231 | F20: DNI | G20: 48249505 | H20: RAMIREZ | I20: POMPA | J20: JORGE LUIS ANTONIO | K20: =CONCATENATE(H20," ",I20," ",J20) -> RAMIREZ POMPA JORGE LUIS ANTONIO | L20: MASCULINO | M20: 34472 | N20: 948526376 | O20: Jorgeluisramirezpompa1@gmail.com | P20: MINERA AURIFERA RETAMAS S.A. | Q20: SAN ANDRES | R20: GRUPO CREDCO EMPRESA DE INGENIERIA, ARQUITECTURA Y CONSTRUCCION S.A.C. | S20: 20601242657 | T20: SUPERFICIE | U20: PROYECTOS E INFRAESTUCTURA | V20: OPERARIO CIVIL | W20: CAJAMARCA | X20: CASERIO ROSAMAYOPATA | Y20: CAJAMARCA | Z20: CAJAMARCA | AA20: CAJAMARCA | AB20: =DATEDIF(M20,TODAY(),"y")&" AÑOS" -> 31 AÑOS | AC20: HUAMACHUCO | AD20: SAN ANDRES | AF20: 45648 | AG20: =DATEDIF(AF20,TODAY(),"Y") -> 1 | AH20: =DATEDIF(AF20,TODAY(),"YM") -> 1 | AI20: =DATEDIF(AF20,TODAY(),"MD") -> 8
A21: 232 | B21: SAN ANDRES | C21: CENTRO MEDICO | D21: GC0000232 | F21: DNI | G21: 75342164 | H21: ROJAS | I21: ABAD | J21: BRYAN DENNIS | K21: =CONCATENATE(H21," ",I21," ",J21) -> ROJAS ABAD BRYAN DENNIS | L21: MASCULINO | M21: 35790 | N21: 938663062 | O21: Bryan_rojas2697@hotmail.com | P21: MINERA AURIFERA RETAMAS S.A. | Q21: SAN ANDRES | R21: GRUPO CREDCO EMPRESA DE INGENIERIA, ARQUITECTURA Y CONSTRUCCION S.A.C. | S21: 20601242657 | T21: SUPERFICIE | U21: PROYECTOS E INFRAESTUCTURA | V21: OPERARIO CIVIL | W21: PIURA | X21: CALLE JOSE MARIA RAYGADA 400 ASENT. H. 9 DE OCTUBRE | Y21: SULLANA | Z21: SULLANA | AA21: PIURA | AB21: =DATEDIF(M21,TODAY(),"y")&" AÑOS" -> 28 AÑOS | AC21: TRUJILLO | AD21: SAN ANDRES | AF21: 45648 | AG21: =DATEDIF(AF21,TODAY(),"Y") -> 1 | AH21: =DATEDIF(AF21,TODAY(),"YM") -> 1 | AI21: =DATEDIF(AF21,TODAY(),"MD") -> 8
A22: 7 | B22: SAN ANDRES | C22: CENTRO MEDICO | D22: GC0000007 | E22: 46148 | F22: DNI | G22: 72444479 | H22: ROJAS | I22: PEÑA | J22: ROSMA ROEL | K22: =CONCATENATE(H22," ",I22," ",J22) -> ROJAS PEÑA ROSMA ROEL | L22: MASCULINO | M22: 34884 | N22: 941260424 | O22: reykin.16@gmail.com | P22: MINERA AURIFERA RETAMAS S.A. | Q22: SAN ANDRES | R22: GRUPO CREDCO EMPRESA DE INGENIERIA, ARQUITECTURA Y CONSTRUCCION S.A.C. | S22: 20601242657 | T22: SUPERFICIE | U22: PROYECTOS E INFRAESTUCTURA | V22: OPERARIO CIVIL | W22: PIURA | X22: ASOCIACION BELEN MZ. B LOT 21 | Y22: CASTILLA | Z22: PIURA | AA22: PIURA | AB22: =DATEDIF(M22,TODAY(),"y")&" AÑOS" -> 30 AÑOS | AC22: TRUJILLO | AD22: SAN ANDRES | AF22: 44266 | AG22: =DATEDIF(AF22,TODAY(),"Y") -> 4 | AH22: =DATEDIF(AF22,TODAY(),"YM") -> 10 | AI22: =DATEDIF(AF22,TODAY(),"MD") -> 19
A23: 163 | B23: SAN ANDRES | C23: CENTRO MEDICO | D23: GC0000163 | F23: DNI | G23: 47084997 | H23: BURGOS | I23: JAYASI | J23: JORGE | K23: =CONCATENATE(H23," ",I23," ",J23) -> BURGOS JAYASI JORGE | L23: MASCULINO | M23: 33402 | N23: 954977215 | O23: jorgeburgosjayasi@gmail.com | P23: MINERA AURIFERA RETAMAS S.A. | Q23: SAN ANDRES | R23: GRUPO CREDCO EMPRESA DE INGENIERIA, ARQUITECTURA Y CONSTRUCCION S.A.C. | S23: 20601242657 | T23: SUPERFICIE | U23: PROYECTOS E INFRAESTUCTURA | V23: OFICIAL CIVIL | W23: CAJAMARCA | X23: CASERIO CHIGDEN | Y23: SAN JUAN | Z23: CAJAMARCA | AA23: CAJAMARCA | AB23: =DATEDIF(M23,TODAY(),"y")&" AÑOS" -> 34 AÑOS | AC23: HUAMACHUCO | AD23: SAN ANDRES | AF23: 44951 | AG23: =DATEDIF(AF23,TODAY(),"Y") -> 3 | AH23: =DATEDIF(AF23,TODAY(),"YM") -> 0 | AI23: =DATEDIF(AF23,TODAY(),"MD") -> 5
A24: 203 | B24: SAN ANDRES | C24: CENTRO MEDICO | D24: GC0000203 | F24: DNI | G24: 47170380 | H24: DURAN | I24: PINEDO | J24: ELI | K24: =CONCATENATE(H24," ",I24," ",J24) -> DURAN PINEDO ELI | L24: MASCULINO | M24: 31649 | N24: 942281106 | O24: Elidu871@gmail.com | P24: MINERA AURIFERA RETAMAS S.A. | Q24: SAN ANDRES | R24: GRUPO CREDCO EMPRESA DE INGENIERIA, ARQUITECTURA Y CONSTRUCCION S.A.C. | S24: 20601242657 | T24: SUPERFICIE | U24: PROYECTOS E INFRAESTUCTURA | V24: OFICIAL CIVIL | W24: CAJAMARCA | X24: PASAJE LOS ANGELES 128 | Y24: CAJAMARCA | Z24: CAJAMARCA | AA24: CAJAMARCA | AB24: =DATEDIF(M24,TODAY(),"y")&" AÑOS" -> 39 AÑOS | AC24: HUAMACHUCO | AD24: SAN ANDRES | AF24: 45316 | AG24: =DATEDIF(AF24,TODAY(),"Y") -> 2 | AH24: =DATEDIF(AF24,TODAY(),"YM") -> 0 | AI24: =DATEDIF(AF24,TODAY(),"MD") -> 5
A25: 96 | B25: SAN ANDRES | C25: CENTRO MEDICO | D25: GC0000096 | E25: 45784 | F25: DNI | G25: 73635435 | H25: LINARES | I25: BLONDET | J25: LUIS II | K25: =CONCATENATE(H25," ",I25," ",J25) -> LINARES BLONDET LUIS II | L25: MASCULINO | M25: 34656 | N25: 961749499 | O25: luislinaresb@hotmail.com | P25: MINERA AURIFERA RETAMAS S.A. | Q25: SAN ANDRES | R25: GRUPO CREDCO EMPRESA DE INGENIERIA, ARQUITECTURA Y CONSTRUCCION S.A.C. | S25: 20601242657 | T25: SUPERFICIE | U25: PROYECTOS E INFRAESTUCTURA | V25: OFICIAL CIVIL | W25: LAMBAYEQUE | X25: CALLE LAS DIAMELAS #160 | Y25: JOSE LEONARDO ORTIZ | Z25: CHICLAYO | AA25: LAMBAYEQUE | AB25: =DATEDIF(M25,TODAY(),"y")&" AÑOS" -> 31 AÑOS | AC25: TRUJILLO | AD25: SAN ANDRES | AF25: 44629 | AG25: =DATEDIF(AF25,TODAY(),"Y") -> 3 | AH25: =DATEDIF(AF25,TODAY(),"YM") -> 10 | AI25: =DATEDIF(AF25,TODAY(),"MD") -> 21
A26: 166 | B26: SAN ANDRES | C26: CENTRO MEDICO | D26: GC0000166 | F26: DNI | G26: 71232355 | H26: LLAMOGA | I26: PINEDO | J26: JAIME | K26: =CONCATENATE(H26," ",I26," ",J26) -> LLAMOGA PINEDO JAIME | L26: MASCULINO | M26: 34313 | N26: 987654967 | O26: Llamogapinedoj@gmail.com | P26: MINERA AURIFERA RETAMAS S.A. | Q26: SAN ANDRES | R26: GRUPO CREDCO EMPRESA DE INGENIERIA, ARQUITECTURA Y CONSTRUCCION S.A.C. | S26: 20601242657 | T26: SUPERFICIE | U26: PROYECTOS E INFRAESTUCTURA | V26: OFICIAL CIVIL | W26: CAJAMARCA | X26: AV. TUPAC CAMARU N° 847 | Y26: LLACONARA | Z26: CAJAMARCA | AA26: CAJAMARCA | AB26: =DATEDIF(M26,TODAY(),"y")&" AÑOS" -> 32 AÑOS | AC26: HUAMACHUCO | AD26: SAN ANDRES | AF26: 44965 | AG26: =DATEDIF(AF26,TODAY(),"Y") -> 2 | AH26: =DATEDIF(AF26,TODAY(),"YM") -> 11 | AI26: =DATEDIF(AF26,TODAY(),"MD") -> 22
A27: 179 | B27: SAN ANDRES | C27: CENTRO MEDICO | D27: GC0000179 | F27: DNI | G27: 43211300 | H27: ROJAS | I27: GUERRERO | J27: HILDEBRANDO | K27: =CONCATENATE(H27," ",I27," ",J27) -> ROJAS GUERRERO HILDEBRANDO | L27: MASCULINO | M27: 31331 | N27: 941205078 | O27: hilrojas1985@gmail.com | P27: MINERA AURIFERA RETAMAS S.A. | Q27: SAN ANDRES | R27: GRUPO CREDCO EMPRESA DE INGENIERIA, ARQUITECTURA Y CONSTRUCCION S.A.C. | S27: 20601242657 | T27: SUPERFICIE | U27: PROYECTOS E INFRAESTUCTURA | V27: OFICIAL CIVIL | W27: CAJAMARCA | X27: CASERIO EL PROGRESO | Y27: TUMBADEN | Z27: SAN PABLO | AA27: CAJAMARCA | AB27: =DATEDIF(M27,TODAY(),"y")&" AÑOS" -> 40 AÑOS | AC27: HUAMACHUCO | AD27: SAN ANDRES | AF27: 45125 | AG27: =DATEDIF(AF27,TODAY(),"Y") -> 2 | AH27: =DATEDIF(AF27,TODAY(),"YM") -> 6 | AI27: =DATEDIF(AF27,TODAY(),"MD") -> 12
A28: 29 | B28: SAN ANDRES | C28: CENTRO MEDICO | D28: GC0000029 | F28: DNI | G28: 41068253 | H28: SANCHEZ | I28: MOSQUEIRA | J28: WALTER | K28: =CONCATENATE(H28," ",I28," ",J28) -> SANCHEZ MOSQUEIRA WALTER | L28: MASCULINO | M28: 29037 | N28: 999884640 | O28: walter1134sanchez@gmail.com | P28: MINERA AURIFERA RETAMAS S.A. | Q28: SAN ANDRES | R28: GRUPO CREDCO EMPRESA DE INGENIERIA, ARQUITECTURA Y CONSTRUCCION S.A.C. | S28: 20601242657 | T28: SUPERFICIE | U28: PROYECTOS E INFRAESTUCTURA | V28: OFICIAL CIVIL | W28: CAJAMARCA | X28: Psj. El Carme s/n | Y28: CAJAMARCA | Z28: CAJAMARCA | AA28: CAJAMARCA | AB28: =DATEDIF(M28,TODAY(),"y")&" AÑOS" -> 46 AÑOS | AC28: HUAMACHUCO | AD28: SAN ANDRES | AF28: 44288 | AG28: =DATEDIF(AF28,TODAY(),"Y") -> 4 | AH28: =DATEDIF(AF28,TODAY(),"YM") -> 9 | AI28: =DATEDIF(AF28,TODAY(),"MD") -> 28
A29: 212 | B29: SAN ANDRES | C29: CENTRO MEDICO | D29: GC0000212 | F29: DNI | G29: 70137236 | H29: TISNADO | I29: ARRESTEGUI | J29: GERSON YADER | K29: =CONCATENATE(H29," ",I29," ",J29) -> TISNADO ARRESTEGUI GERSON YADER | L29: MASCULINO | M29: 36192 | N29: 960696017 | O29: tisnadoarresteguig@gmail.com | P29: MINERA AURIFERA RETAMAS S.A. | Q29: SAN ANDRES | R29: GRUPO CREDCO EMPRESA DE INGENIERIA, ARQUITECTURA Y CONSTRUCCION S.A.C. | S29: 20601242657 | T29: SUPERFICIE | U29: PROYECTOS E INFRAESTUCTURA | V29: AYUDANTE CIVIL | W29: CAJAMARCA | X29: CASERIO SANTA CATALINA | Y29: CUPISNIQUE | Z29: CONTUMAZA | AA29: CAJAMARCA | AB29: =DATEDIF(M29,TODAY(),"y")&" AÑOS" -> 26 AÑOS | AC29: TRUJILLO | AD29: SAN ANDRES | AF29: 45353 | AG29: =DATEDIF(AF29,TODAY(),"Y") -> 1 | AH29: =DATEDIF(AF29,TODAY(),"YM") -> 10 | AI29: =DATEDIF(AF29,TODAY(),"MD") -> 28
A30: 85 | B30: SAN ANDRES | C30: CENTRO MEDICO | D30: GC0000085 | F30: DNI | G30: 71713031 | H30: ARIAS | I30: ARCE | J30: WILMER | K30: =CONCATENATE(H30," ",I30," ",J30) -> ARIAS ARCE WILMER | L30: MASCULINO | M30: 34868 | N30: 982394253 | O30: Wilsonariasarce@gmail.com | P30: MINERA AURIFERA RETAMAS S.A. | Q30: SAN ANDRES | R30: GRUPO CREDCO EMPRESA DE INGENIERIA, ARQUITECTURA Y CONSTRUCCION S.A.C. | S30: 20601242657 | T30: SUPERFICIE | U30: PROYECTOS E INFRAESTUCTURA | V30: AYUDANTE CIVIL | W30: HUAMACHUCO | X30: CASERIO PARANSHIQUE LOT 34 | Y30: HUAMACHUCO | Z30: SANCHEZ CARRION | AA30: LA LIBERTAD | AB30: =DATEDIF(M30,TODAY(),"y")&" AÑOS" -> 30 AÑOS | AC30: HUAMACHUCO | AD30: SAN ANDRES | AF30: 44545 | AG30: =DATEDIF(AF30,TODAY(),"Y") -> 4 | AH30: =DATEDIF(AF30,TODAY(),"YM") -> 1 | AI30: =DATEDIF(AF30,TODAY(),"MD") -> 15
A31: 114 | B31: SAN ANDRES | C31: CENTRO MEDICO | D31: GC0000114 | F31: DNI | G31: 70210174 | H31: ARRIBASPLATA | I31: ARRIBASPLATA | J31: YEISON ANTONI | K31: =CONCATENATE(H31," ",I31," ",J31) -> ARRIBASPLATA ARRIBASPLATA YEISON ANTONI | L31: MASCULINO | M31: 35077 | N31: 963513817 | O31: yeiz_123@hotmail.com | P31: MINERA AURIFERA RETAMAS S.A. | Q31: SAN ANDRES | R31: GRUPO CREDCO EMPRESA DE INGENIERIA, ARQUITECTURA Y CONSTRUCCION S.A.C. | S31: 20601242657 | T31: SUPERFICIE | U31: PROYECTOS E INFRAESTUCTURA | V31: AYUDANTE CIVIL | W31: CAJAMARCA | X31: AV.PERU 1273 | Y31: CAJAMARCA | Z31: CAJAMARCA | AA31: CAJAMARCA | AB31: =DATEDIF(M31,TODAY(),"y")&" AÑOS" -> 30 AÑOS | AC31: HUAMACHUCO | AD31: SAN ANDRES | AF31: 44804 | AG31: =DATEDIF(AF31,TODAY(),"Y") -> 3 | AH31: =DATEDIF(AF31,TODAY(),"YM") -> 4 | AI31: =DATEDIF(AF31,TODAY(),"MD") -> 30
A32: 118 | B32: SAN ANDRES | C32: CENTRO MEDICO | D32: GC0000118 | E32: 45784 | F32: DNI | G32: 41534039 | H32: CARHUAPOMA | I32: VARGAS | J32: OSWALDO | K32: =CONCATENATE(H32," ",I32," ",J32) -> CARHUAPOMA VARGAS OSWALDO | L32: MASCULINO | M32: 30181 | N32: 971173092 | O32: Oswaldocarhuapoma27 | P32: MINERA AURIFERA RETAMAS S.A. | Q32: SAN ANDRES | R32: GRUPO CREDCO EMPRESA DE INGENIERIA, ARQUITECTURA Y CONSTRUCCION S.A.C. | S32: 20601242657 | T32: SUPERFICIE | U32: PROYECTOS E INFRAESTUCTURA | V32: AYUDANTE CIVIL | W32: LAMBAYEQUE | X32: CALLE SAN FRANCISCO 739-URRUNAGA | Y32: JOSE LEONARDO ORTIZ | Z32: CHICLAYO | AA32: LAMBAYEQUE | AB32: =DATEDIF(M32,TODAY(),"y")&" AÑOS" -> 43 AÑOS | AC32: TRUJILLO | AD32: SAN ANDRES | AF32: 44818 | AG32: =DATEDIF(AF32,TODAY(),"Y") -> 3 | AH32: =DATEDIF(AF32,TODAY(),"YM") -> 4 | AI32: =DATEDIF(AF32,TODAY(),"MD") -> 16
A33: 235 | B33: SAN ANDRES | C33: CENTRO MEDICO | D33: GC0000235 | F33: DNI | G33: 75848903 | H33: CARRILLO | I33: ZAPATA | J33: CARLOS EDUARDO | K33: =CONCATENATE(H33," ",I33," ",J33) -> CARRILLO ZAPATA CARLOS EDUARDO | L33: MASCULINO | M33: 36839 | N33: 981110098 | O33: Carloscarrillo1110@hotmail.com | P33: MINERA AURIFERA RETAMAS S.A. | Q33: SAN ANDRES | R33: GRUPO CREDCO EMPRESA DE INGENIERIA, ARQUITECTURA Y CONSTRUCCION S.A.C. | S33: 20601242657 | T33: SUPERFICIE | U33: PROYECTOS E INFRAESTUCTURA | V33: AYUDANTE CIVIL | W33: PIURA | X33: ASENT. H. JORGE CHAVEZ Y9 | Y33: SULLANA | Z33: SULLANA | AA33: PIURA | AB33: =DATEDIF(M33,TODAY(),"y")&" AÑOS" -> 25 AÑOS | AC33: TRUJILLO | AD33: SAN ANDRES | AF33: 45687 | AG33: =DATEDIF(AF33,TODAY(),"Y") -> 1 | AH33: =DATEDIF(AF33,TODAY(),"YM") -> 0 | AI33: =DATEDIF(AF33,TODAY(),"MD") -> 0
A34: 246 | B34: SAN ANDRES | C34: CENTRO MEDICO | D34: GC0000246 | F34: DNI | G34: 47722881 | H34: CHUQUIMANGO | I34: RAMOS | J34: DIOVER YULINIO | K34: =CONCATENATE(H34," ",I34," ",J34) -> CHUQUIMANGO RAMOS DIOVER YULINIO | L34: MASCULINO | M34: 34061 | N34: 993086901 | O34: yuliniochuquimango@gmail.com | P34: MINERA AURIFERA RETAMAS S.A. | Q34: SAN ANDRES | R34: GRUPO CREDCO EMPRESA DE INGENIERIA, ARQUITECTURA Y CONSTRUCCION S.A.C. | S34: 20601242657 | T34: SUPERFICIE | U34: PROYECTOS E INFRAESTUCTURA | V34: AYUDANTE CIVIL | W34: CAJAMARCA | X34: CARR. VENECIA - EL TRIUNFO S/N CASERIO EL TRIUNFO | Y34: BAÑOS DEL INCA | Z34: CAJAMARCA | AA34: CAJAMARCA | AB34: =DATEDIF(M34,TODAY(),"y")&" AÑOS" -> 32 AÑOS | AC34: HUAMACHUCO | AD34: SAN ANDRES | AF34: 45743 | AG34: =DATEDIF(AF34,TODAY(),"Y") -> 0 | AH34: =DATEDIF(AF34,TODAY(),"YM") -> 10 | AI34: =DATEDIF(AF34,TODAY(),"MD") -> 3
A35: 241 | B35: SAN ANDRES | C35: CENTRO MEDICO | D35: GC0000241 | E35: 45784 | F35: DNI | G35: 47697810 | H35: DELAO | I35: TORRES | J35: BRUNO | K35: =CONCATENATE(H35," ",I35," ",J35) -> DELAO TORRES BRUNO | L35: MASCULINO | M35: 33263 | N35: 963544564 | O35: brunodelaotorres25@gmail.com | P35: MINERA AURIFERA RETAMAS S.A. | Q35: SAN ANDRES | R35: GRUPO CREDCO EMPRESA DE INGENIERIA, ARQUITECTURA Y CONSTRUCCION S.A.C. | S35: 20601242657 | T35: SUPERFICIE | U35: PROYECTOS E INFRAESTUCTURA | V35: AYUDANTE CIVIL | W35: LIMA | X35: JR. GONZALES PRADA S/N | Y35: ATE | Z35: LIMA | AA35: LIMA | AB35: =DATEDIF(M35,TODAY(),"y")&" AÑOS" -> 35 AÑOS | AC35: TRUJILLO | AD35: SAN ANDRES | AF35: 45694 | AG35: =DATEDIF(AF35,TODAY(),"Y") -> 0 | AH35: =DATEDIF(AF35,TODAY(),"YM") -> 11 | AI35: =DATEDIF(AF35,TODAY(),"MD") -> 24
A36: 221 | B36: SAN ANDRES | C36: CENTRO MEDICO | D36: GC0000221 | F36: DNI | G36: 72944466 | H36: JARA | I36: DE LA CRUZ | J36: BENAVIDES | K36: =CONCATENATE(H36," ",I36," ",J36) -> JARA DE LA CRUZ BENAVIDES | L36: MASCULINO | M36: 35829 | N36: 932298906 | O36: jarabenavides7@gmail.com | P36: MINERA AURIFERA RETAMAS S.A. | Q36: SAN ANDRES | R36: GRUPO CREDCO EMPRESA DE INGENIERIA, ARQUITECTURA Y CONSTRUCCION S.A.C. | S36: 20601242657 | T36: SUPERFICIE | U36: PROYECTOS E INFRAESTUCTURA | V36: OFICIAL CIVIL | W36: CAJAMARCA | X36: BARRIO SAN VICENTE S/N | Y36: CAJAMARCA | Z36: CAJAMARCA | AA36: CAJAMARCA | AB36: =DATEDIF(M36,TODAY(),"y")&" AÑOS" -> 27 AÑOS | AC36: HUAMACHUCO | AD36: SAN ANDRES | AF36: 45491 | AG36: =DATEDIF(AF36,TODAY(),"Y") -> 1 | AH36: =DATEDIF(AF36,TODAY(),"YM") -> 6 | AI36: =DATEDIF(AF36,TODAY(),"MD") -> 12
A37: 186 | B37: SAN ANDRES | C37: CENTRO MEDICO | D37: GC0000186 | F37: DNI | G37: 74206233 | H37: LLANOS | I37: LOPEZ | J37: JAIME LUIS | K37: =CONCATENATE(H37," ",I37," ",J37) -> LLANOS LOPEZ JAIME LUIS | L37: MASCULINO | M37: 35000 | N37: 997573190 | O37: luisllanos077@gmail.com | P37: MINERA AURIFERA RETAMAS S.A. | Q37: SAN ANDRES | R37: GRUPO CREDCO EMPRESA DE INGENIERIA, ARQUITECTURA Y CONSTRUCCION S.A.C. | S37: 20601242657 | T37: SUPERFICIE | U37: PROYECTOS E INFRAESTUCTURA | V37: AYUDANTE CIVIL | W37: CAJAMARCA | X37: CASERIO AGOCUCHO | Y37: CAJAMARCA | Z37: CAJAMARCA | AA37: CAJAMARCA | AB37: =DATEDIF(M37,TODAY(),"y")&" AÑOS" -> 30 AÑOS | AC37: HUAMACHUCO | AD37: SAN ANDRES | AF37: 45182 | AG37: =DATEDIF(AF37,TODAY(),"Y") -> 2 | AH37: =DATEDIF(AF37,TODAY(),"YM") -> 4 | AI37: =DATEDIF(AF37,TODAY(),"MD") -> 17
A38: 182 | B38: SAN ANDRES | C38: CENTRO MEDICO | D38: GC0000182 | F38: DNI | G38: 71758207 | H38: LINARES | I38: RAMIREZ | J38: WILLIAM ALI | K38: =CONCATENATE(H38," ",I38," ",J38) -> LINARES RAMIREZ WILLIAM ALI | L38: MASCULINO | M38: 35846 | N38: 997497655 | O38: wlinare907@gmail.com | P38: MINERA AURIFERA RETAMAS S.A. | Q38: SAN ANDRES | R38: GRUPO CREDCO EMPRESA DE INGENIERIA, ARQUITECTURA Y CONSTRUCCION S.A.C. | S38: 20601242657 | T38: SUPERFICIE | U38: PROYECTOS E INFRAESTUCTURA | V38: AYUDANTE CIVIL | W38: CAJAMARCA | X38: CASERIO CHIGDEN | Y38: CAJAMARCA | Z38: CAJAMARCA | AA38: CAJAMARCA | AB38: =DATEDIF(M38,TODAY(),"y")&" AÑOS" -> 27 AÑOS | AC38: HUAMACHUCO | AD38: SAN ANDRES | AF38: 45154 | AG38: =DATEDIF(AF38,TODAY(),"Y") -> 2 | AH38: =DATEDIF(AF38,TODAY(),"YM") -> 5 | AI38: =DATEDIF(AF38,TODAY(),"MD") -> 14
A39: 201 | B39: SAN ANDRES | C39: CENTRO MEDICO | D39: GC0000201 | F39: DNI | G39: 76352395 | H39: MIRANDA | I39: GALLARDO | J39: SEGUNDO EDUARDO | K39: =CONCATENATE(H39," ",I39," ",J39) -> MIRANDA GALLARDO SEGUNDO EDUARDO | L39: MASCULINO | M39: 35181 | N39: 980269415 | O39: middle-e@hotmail.com | P39: MINERA AURIFERA RETAMAS S.A. | Q39: SAN ANDRES | R39: GRUPO CREDCO EMPRESA DE INGENIERIA, ARQUITECTURA Y CONSTRUCCION S.A.C. | S39: 20601242657 | T39: SUPERFICIE | U39: PROYECTOS E INFRAESTUCTURA | V39: AYUDANTE CIVIL | W39: CAJAMARCA | X39: CENTRO POBLADO DE PARIAMARCA | Y39: CAJAMARCA | Z39: CAJAMARCA | AA39: CAJAMARCA | AB39: =DATEDIF(M39,TODAY(),"y")&" AÑOS" -> 29 AÑOS | AC39: HUAMACHUCO | AD39: SAN ANDRES | AF39: 45316 | AG39: =DATEDIF(AF39,TODAY(),"Y") -> 2 | AH39: =DATEDIF(AF39,TODAY(),"YM") -> 0 | AI39: =DATEDIF(AF39,TODAY(),"MD") -> 5
A40: 191 | B40: SAN ANDRES | C40: CENTRO MEDICO | D40: GC0000191 | F40: DNI | G40: 74083999 | H40: PISCO | I40: PINEDO | J40: JHONATAN KEVIN | K40: =CONCATENATE(H40," ",I40," ",J40) -> PISCO PINEDO JHONATAN KEVIN | L40: MASCULINO | M40: 36856 | N40: 965057215 | O40: jonathankevinpiscopinedo@gmail.com | P40: MINERA AURIFERA RETAMAS S.A. | Q40: SAN ANDRES | R40: GRUPO CREDCO EMPRESA DE INGENIERIA, ARQUITECTURA Y CONSTRUCCION S.A.C. | S40: 20601242657 | T40: SUPERFICIE | U40: PROYECTOS E INFRAESTUCTURA | V40: AYUDANTE CIVIL | W40: CAJAMARCA | X40: JR. ALFONSO UGARTE INT. A BARRIO MOLLEPAMPA MZ. A LOT. 1 | Y40: CAJAMARCA | Z40: CAJAMARCA | AA40: CAJAMARCA | AB40: =DATEDIF(M40,TODAY(),"y")&" AÑOS" -> 25 AÑOS | AC40: HUAMACHUCO | AD40: SAN ANDRES | AF40: 45210 | AG40: =DATEDIF(AF40,TODAY(),"Y") -> 2 | AH40: =DATEDIF(AF40,TODAY(),"YM") -> 3 | AI40: =DATEDIF(AF40,TODAY(),"MD") -> 19
A41: 227 | B41: SAN ANDRES | C41: CENTRO MEDICO | D41: GC0000227 | F41: DNI | G41: 44425798 | H41: TANTA | I41: DE LA CRUZ | J41: SANTOS | K41: =CONCATENATE(H41," ",I41," ",J41) -> TANTA DE LA CRUZ SANTOS | L41: MASCULINO | M41: 32007 | N41: 936 586 186 | O41: santostantadelacruz625@gmail.com | P41: MINERA AURIFERA RETAMAS S.A. | Q41: SAN ANDRES | R41: GRUPO CREDCO EMPRESA DE INGENIERIA, ARQUITECTURA Y CONSTRUCCION S.A.C. | S41: 20601242657 | T41: SUPERFICIE | U41: PROYECTOS E INFRAESTUCTURA | V41: AYUDANTE CIVIL | W41: CAJAMARCA | X41: CASERIO CASADEN | Y41: MAGDALENA | Z41: CAJAMARCA | AA41: CAJAMARCA | AB41: =DATEDIF(M41,TODAY(),"y")&" AÑOS" -> 38 AÑOS | AC41: HUAMACHUCO | AD41: SAN ANDRES | AF41: 45603 | AG41: =DATEDIF(AF41,TODAY(),"Y") -> 1 | AH41: =DATEDIF(AF41,TODAY(),"YM") -> 2 | AI41: =DATEDIF(AF41,TODAY(),"MD") -> 23
A42: 200 | B42: SAN ANDRES | C42: CENTRO MEDICO | D42: GC0000200 | F42: DNI | G42: 45095942 | H42: VENEGAS | I42: RAMOS | J42: ENRIQUE HERMIS | K42: =CONCATENATE(H42," ",I42," ",J42) -> VENEGAS RAMOS ENRIQUE HERMIS | L42: MASCULINO | M42: 31800 | N42: 92366477 | O42: cristofer230201@gmail.com | P42: MINERA AURIFERA RETAMAS S.A. | Q42: SAN ANDRES | R42: GRUPO CREDCO EMPRESA DE INGENIERIA, ARQUITECTURA Y CONSTRUCCION S.A.C. | S42: 20601242657 | T42: SUPERFICIE | U42: PROYECTOS E INFRAESTUCTURA | V42: AYUDANTE CIVIL | W42: LAMBAYEQUE | X42: PUEBLO JOVEN SAN RAFAEL CALLE EL TUME MZ J LT. 3 | Y42: LA VICTORIA | Z42: CHICLAYO | AA42: LAMBAYEQUE | AB42: =DATEDIF(M42,TODAY(),"y")&" AÑOS" -> 39 AÑOS | AC42: TRUJILLO | AD42: SAN ANDRES | AF42: 45273 | AG42: =DATEDIF(AF42,TODAY(),"Y") -> 2 | AH42: =DATEDIF(AF42,TODAY(),"YM") -> 1 | AI42: =DATEDIF(AF42,TODAY(),"MD") -> 17
...

Sheet PERSONAL CESADO
H3: PERSONAL DE BAJA
A4: N° | B4: SEDE | C4: CLÍNICA | D4: CODIGO | E4: FECHA DE ATENCION (dd/mm/yyyy) | F4: TIPO DOCUMENTO | G4: NRO DOCUMENTO | H4: APELLIDO PATERNO | I4: APELLIDO MATERNO | J4: NOMBRES | K4: APELLIDOS Y NOMBRES COMPLETOS (NO TOCAR ESTA FILA) | L4: SEXO | M4: FECHA NACIMIENTO (dd/mm/aaaa) | N4: CELULAR | O4: CORREO | P4: COMPAÑÍA | Q4: UNIDAD | R4: EMPRESA CONTRATISTA | S4: RUC (Empresa Contratista) | T4: ZONA DE TRABAJO | U4: AREA DE TRABAJO | V4: PUESTO | W4: UBICACIÓN | X4: DIRECCION | Y4: DISTRITO | Z4: PROVINCIA | AA4: DEPARTAMENTO | AB4: EDAD | AC4: DESTINO | AD4: LUGAR DE EMBARQUE (SAN ANDRES, BUENOS AIRES, CEO, CHILCAS OESTE) | AE4: STATUS P1, P2, P3, P4, INMUNE | AF4: FECHA DE INGRESO | AG4: TIEMPO EN UNIDAD | AJ4: FECHA DE BAJA | AK4: OBSERVACIONES
A5: 1 | B5: SAN ANDRES | C5: CENTRO MEDICO | D5: GC0000001 | F5: DNI | G5: 42293346 | H5: MAYTA | I5: PACHECO | J5: ERICK ANTHONY | K5: =CONCATENATE(H5," ",I5," ",J5) -> MAYTA PACHECO ERICK ANTHONY | L5: MASCULINO | M5: 30695 | N5: 987782404 | O5: erick.mayta@grupocredco.com | P5: MINERA AURIFERA RETAMAS S.A. | Q5: SAN ANDRES | R5: GRUPO CREDCO EMPRESA DE INGENIERIA, ARQUITECTURA Y CONSTRUCCION S.A.C. | S5: 20601242657 | T5: SUPERFICIE | U5: PROYECTOS E INFRAESTUCTURA | V5: RESIDENTE DE OBRA | W5: CAJAMARCA | X5: URB. RAMON CASTILLA PSJ. JAEN 131 | Y5: CAJAMARCA | Z5: CAJAMARCA | AA5: CAJAMARCA | AB5: 37 | AC5: HUAMACHUCO | AD5: SAN ANDRES | AF5: 44253
A6: 3 | B6: SAN ANDRES | C6: CENTRO MEDICO | D6: GC0000006 | F6: DNI | G6: 08067813 | H6: VERAMENDI | I6: FLORES | J6: ROBERTO GERMAN | K6: =CONCATENATE(H6," ",I6," ",J6) -> VERAMENDI FLORES ROBERTO GERMAN | L6: MASCULINO | M6: 23493 | N6: 987782404 | O6: roberto.veramendi@gruócredco.com | P6: MINERA AURIFERA RETAMAS S.A. | Q6: SAN ANDRES | R6: GRUPO CREDCO EMPRESA DE INGENIERIA, ARQUITECTURA Y CONSTRUCCION S.A.C. | S6: 20601242657 | T6: SUPERFICIE | U6: PROYECTOS E INFRAESTUCTURA | V6: RESIDENTE DE OBRA | W6: LIMA | X6: A.A. HH. "VALLE HERMOSO" 3ERA ZONA COLLIQUE-COMAS | Y6: COMAS | Z6: LIMA | AA6: LIMA | AB6: 57 | AC6: TRUJILLO | AD6: SAN ANDRES | AF6: 44258
A7: 4 | B7: SAN ANDRES | C7: CENTRO MEDICO | D7: GC0000024 | F7: DNI | G7: 73772552 | H7: BOCANEGRA | I7: MIRANDA | J7: AYLTHON ELMAN | K7: =CONCATENATE(H7," ",I7," ",J7) -> BOCANEGRA MIRANDA AYLTHON ELMAN | L7: MASCULINO | M7: 35618 | N7: 955662120 | O7: ayltbm@gmail.com. RENUNCIO | P7: MINERA AURIFERA RETAMAS S.A. | Q7: SAN ANDRES | R7: GRUPO CREDCO EMPRESA DE INGENIERIA, ARQUITECTURA Y CONSTRUCCION S.A.C. | S7: 20601242662 | T7: SUPERFICIE | U7: PROYECTOS E INFRAESTUCTURA | V7: ASISTENTE DE OBRA | W7: TRUJILLO | X7: AV. LA MARINA 46 PISO 1 CURVA SUN | Y7: TRUJILLO | Z7: TRUJILLO | AA7: LA LIBERTAD | AB7: 23 | AC7: UNIDAD MINERA | AD7: TRUJILLO
A8: 10 | B8: SAN ANDRES | C8: CENTRO MEDICO | D8: GC0000004 | F8: DNI | G8: 71832253 | H8: COLORADO | I8: ESCOBAL | J8: RONALDINI | K8: =CONCATENATE(H8," ",I8," ",J8) -> COLORADO ESCOBAL RONALDINI | L8: MASCULINO | M8: 36291 | N8: 997154038 | O8: RENUNCIO | P8: MINERA AURIFERA RETAMAS S.A. | Q8: SAN ANDRES | R8: GRUPO CREDCO EMPRESA DE INGENIERIA, ARQUITECTURA Y CONSTRUCCION S.A.C. | S8: 20601242662 | T8: SUPERFICIE | U8: PROYECTOS E INFRAESTUCTURA | V8: PEON CIVIL | W8: CAJAMARCA | X8: CASERIO LAGUNA SANTA URSULA | Y8: CAJAMARCA | Z8: CAJAMARCA | AA8: CAJAMARCA | AB8: 21 | AC8: UNIDAD MINERA | AD8: TRUJILLO
A9: 11 | B9: SAN ANDRES | C9: CENTRO MEDICO | D9: GC0000008 | F9: DNI | G9: 40990473 | H9: CUEVA | I9: CUEVA | J9: LUIS | K9: =CONCATENATE(H9," ",I9," ",J9) -> CUEVA CUEVA LUIS | L9: MASCULINO | M9: 28744 | N9: 976563836 | O9: RENUNCIO | P9: MINERA AURIFERA RETAMAS S.A. | Q9: SAN ANDRES | R9: GRUPO CREDCO EMPRESA DE INGENIERIA, ARQUITECTURA Y CONSTRUCCION S.A.C. | S9: 20601242657 | T9: SUPERFICIE | U9: PROYECTOS E INFRAESTUCTURA | V9: OPERARIO CIVIL | W9: CAJAMARCA | X9: CASERIO PORCONCILLO | Y9: CAJAMARCA | Z9: CAJAMARCA | AA9: CAJAMARCA | AB9: 42 | AC9: UNIDAD MINERA | AD9: TRUJILLO
A10: 12 | B10: SAN ANDRES | C10: CENTRO MEDICO | D10: GC0000010 | F10: DNI | G10: 72426561 | H10: CUEVA | I10: HAUMAN | J10: WILMER LUIS | K10: =CONCATENATE(H10," ",I10," ",J10) -> CUEVA HAUMAN WILMER LUIS | L10: MASCULINO | M10: 36144 | N10: 950526271 | O10: RENUNCIO | P10: MINERA AURIFERA RETAMAS S.A. | Q10: SAN ANDRES | R10: GRUPO CREDCO EMPRESA DE INGENIERIA, ARQUITECTURA Y CONSTRUCCION S.A.C. | S10: 20601242657 | T10: SUPERFICIE | U10: PROYECTOS E INFRAESTUCTURA | V10: PEON CIVIL | W10: CAJAMARCA | X10: CASERIO PORCONCILLO | Y10: CAJAMARCA | Z10: CAJAMARCA | AA10: CAJAMARCA | AB10: 22 | AC10: UNIDAD MINERA | AD10: TRUJILLO
A11: 13 | B11: SAN ANDRES | C11: CENTRO MEDICO | D11: GC0000018 | F11: DNI | G11: 80626308 | H11: CUEVA | I11: ISPILCO | J11: JOSE ELIGIO | K11: =CONCATENATE(H11," ",I11," ",J11) -> CUEVA ISPILCO JOSE ELIGIO | L11: MASCULINO | M11: 28827 | N11: 976500940 | O11: RENUNCIO | P11: MINERA AURIFERA RETAMAS S.A. | Q11: SAN ANDRES | R11: GRUPO CREDCO EMPRESA DE INGENIERIA, ARQUITECTURA Y CONSTRUCCION S.A.C. | S11: 20601242657 | T11: SUPERFICIE | U11: PROYECTOS E INFRAESTUCTURA | V11: ASISTENTE TECNICO CIVIL | W11: CAJAMARCA | X11: Centro Poblado Porcon Bajo | Y11: CAJAMARCA | Z11: CAJAMARCA | AA11: CAJAMARCA | AB11: 42 | AC11: UNIDAD MINERA | AD11: TRUJILLO
A12: 14 | B12: SAN ANDRES | C12: CENTRO MEDICO | D12: GC0000020 | F12: DNI | G12: 46973132 | H12: INFANTE | I12: INFANTE | J12: NESTOR | K12: =CONCATENATE(H12," ",I12," ",J12) -> INFANTE INFANTE NESTOR | L12: MASCULINO | M12: 33546 | N12: 943413773 | O12: RENUNCIO | P12: MINERA AURIFERA RETAMAS S.A. | Q12: SAN ANDRES | R12: GRUPO CREDCO EMPRESA DE INGENIERIA, ARQUITECTURA Y CONSTRUCCION S.A.C. | S12: 20601242657 | T12: SUPERFICIE | U12: PROYECTOS E INFRAESTUCTURA | V12: ASISTENTE TECNICO CIVIL | W12: CAJAMARCA | X12: CA. Caserio Unigan | Y12: CAJAMARCA | Z12: CAJAMARCA | AA12: CAJAMARCA | AB12: 29 | AC12: UNIDAD MINERA | AD12: TRUJILLO
A13: 16 | B13: SAN ANDRES | C13: CENTRO MEDICO | D13: GC0000015 | F13: DNI | G13: 80610247 | H13: MESTANZA | I13: CALDERON | J13: CARMELO | K13: =CONCATENATE(H13," ",I13," ",J13) -> MESTANZA CALDERON CARMELO | L13: MASCULINO | M13: 29050 | N13: 950819893 | O13: RENUNCIO | P13: MINERA AURIFERA RETAMAS S.A. | Q13: SAN ANDRES | R13: GRUPO CREDCO EMPRESA DE INGENIERIA, ARQUITECTURA Y CONSTRUCCION S.A.C. | S13: 20601242657 | T13: SUPERFICIE | U13: PROYECTOS E INFRAESTUCTURA | V13: TECNICO CIVIL | W13: CAJAMARCA | X13: Caserio chigden | Y13: CAJAMARCA | Z13: CAJAMARCA | AA13: CAJAMARCA | AB13: 41 | AC13: UNIDAD MINERA | AD13: TRUJILLO
A14: 19 | B14: SAN ANDRES | C14: CENTRO MEDICO | D14: GC0000021 | F14: DNI | G14: 71770676 | H14: SALAZAR | I14: ARCE | J14: GINO | K14: =CONCATENATE(H14," ",I14," ",J14) -> SALAZAR ARCE GINO | L14: MASCULINO | M14: 36139 | N14: 953944807 | O14: RENUNCIO | P14: MINERA AURIFERA RETAMAS S.A. | Q14: SAN ANDRES | R14: GRUPO CREDCO EMPRESA DE INGENIERIA, ARQUITECTURA Y CONSTRUCCION S.A.C. | S14: 20601242657 | T14: SUPERFICIE | U14: PROYECTOS E INFRAESTUCTURA | V14: PEONCIVIL | W14: CAJAMARCA | X14: Caserio chigden | Y14: CAJAMARCA | Z14: CAJAMARCA | AA14: CAJAMARCA | AB14: 22 | AC14: UNIDAD MINERA | AD14: TRUJILLO
A15: 20 | B15: SAN ANDRES | C15: CENTRO MEDICO | D15: GC0000023 | F15: DNI | G15: 76769149 | H15: CHUQUIMANGO | I15: LOPEZ | J15: GENARO | K15: =CONCATENATE(H15," ",I15," ",J15) -> CHUQUIMANGO LOPEZ GENARO | L15: MASCULINO | M15: 35525 | N15: 913237775 | O15: RENUNCIO | P15: MINERA AURIFERA RETAMAS S.A. | Q15: SAN ANDRES | R15: GRUPO CREDCO EMPRESA DE INGENIERIA, ARQUITECTURA Y CONSTRUCCION S.A.C. | S15: 20601242657 | T15: SUPERFICIE | U15: PROYECTOS E INFRAESTUCTURA | V15: PEON CIVIL | W15: CAJAMARCA | X15: Jiron los frailones S/N Lt. Los Angeles | Y15: CAJAMARCA | Z15: CAJAMARCA | AA15: CAJAMARCA | AB15: 23 | AC15: UNIDAD MINERA | AD15: TRUJILLO
A16: 21 | B16: SAN ANDRES | C16: CENTRO MEDICO | D16: AFILIADO | F16: DNI | G16: 43718042 | H16: MATEO | I16: TANTACHUCO | J16: JORGE JAVIER | K16: =CONCATENATE(H16," ",I16," ",J16) -> MATEO TANTACHUCO JORGE JAVIER | L16: MASCULINO | M16: 31528 | N16: 941535850 | O16: RENUNCIO | P16: MINERA AURIFERA RETAMAS S.A. | Q16: SAN ANDRES | R16: GRUPO CREDCO EMPRESA DE INGENIERIA, ARQUITECTURA Y CONSTRUCCION S.A.C. | S16: 20601242657 | T16: SUPERFICIE | U16: PROYECTOS E INFRAESTUCTURA | V16: CAPATAZ | W16: TRUJILLO | X16: Jose Balta 145 | Y16: REQUE | Z16: CHICLAYO | AA16: LAMBAYEQUE | AB16: 34 | AC16: UNIDAD MINERA | AD16: TRUJILLO
A17: 1 | B17: SAN ANDRES | C17: CENTRO MEDICO | D17: GC0000032 | F17: DNI | G17: 40756835 | H17: TERAN | I17: HUAMAN | J17: OSCAR | K17: =CONCATENATE(H17," ",I17," ",J17) -> TERAN HUAMAN OSCAR | L17: MASCULINO | M17: 32868 | N17: 917029852 | O17: RENUNCIO | P17: MINERA AURIFERA RETAMAS S.A. | Q17: SAN ANDRES | R17: GRUPO CREDCO EMPRESA DE INGENIERIA, ARQUITECTURA Y CONSTRUCCION S.A.C. | S17: 20601242657 | T17: SUPERFICIE | U17: PROYECTOS E INFRAESTUCTURA | V17: TECNICO CIVIL | W17: TRUJILLO | X17: Quinta Alex Mz. A L. 21 | Y17: CHEPEN | Z17: CHEPEN | AA17: LA LIBERTAD | AB17: 31 | AC17: UNIDAD MINERA | AD17: TRUJILLO
A18: 2 | B18: SAN ANDRES | C18: CENTRO MEDICO | D18: GC0000034 | F18: DNI | G18: 41922354 | H18: ULLOA | I18: VALVERDE | J18: JOSE DAVID | K18: =CONCATENATE(H18," ",I18," ",J18) -> ULLOA VALVERDE JOSE DAVID | L18: MASCULINO | M18: 30378 | N18: 967585952 | O18: RENUNCIO | P18: MINERA AURIFERA RETAMAS S.A. | Q18: SAN ANDRES | R18: GRUPO CREDCO EMPRESA DE INGENIERIA, ARQUITECTURA Y CONSTRUCCION S.A.C. | S18: 20601242657 | T18: SUPERFICIE | U18: PROYECTOS E INFRAESTUCTURA | V18: PEON CIVIL | W18: TRUJILLO | X18: Jose Olaya N# 20 | Y18: CHICLIN | Z18: ASCOPE | AA18: LA LIBERTAD | AB18: 37 | AC18: UNIDAD MINERA | AD18: TRUJILLO
A19: 3 | B19: SAN ANDRES | C19: CENTRO MEDICO | D19: GC0000027 | F19: DNI | G19: 76596403 | H19: GUEVARA | I19: ARAUJO | J19: CRISTIAN BRISNEY | K19: =CONCATENATE(H19," ",I19," ",J19) -> GUEVARA ARAUJO CRISTIAN BRISNEY | L19: MASCULINO | M19: 36516 | N19: 900797319 | O19: RENUNCIO | P19: MINERA AURIFERA RETAMAS S.A. | Q19: SAN ANDRES | R19: GRUPO CREDCO EMPRESA DE INGENIERIA, ARQUITECTURA Y CONSTRUCCION S.A.C. | S19: 20601242657 | T19: SUPERFICIE | U19: PROYECTOS E INFRAESTUCTURA | V19: PEON CIVIL | W19: TRUJILLO | X19: Caserio Las Delicias | Y19: OYOTUN | Z19: CHICLAYO | AA19: LAMBAYEQUE | AB19: 21 | AC19: UNIDAD MINERA | AD19: TRUJILLO
A20: 5 | B20: SAN ANDRES | C20: CENTRO MEDICO | D20: GC0000031 | F20: DNI | G20: 47814200 | H20: MENDOZA | I20: MARRUFO | J20: PEDRO JORDY | K20: =CONCATENATE(H20," ",I20," ",J20) -> MENDOZA MARRUFO PEDRO JORDY | L20: MASCULINO | M20: 34070 | N20: 967096061 | O20: RENUNCIO | P20: MINERA AURIFERA RETAMAS S.A. | Q20: SAN ANDRES | R20: GRUPO CREDCO EMPRESA DE INGENIERIA, ARQUITECTURA Y CONSTRUCCION S.A.C. | S20: 20601242657 | T20: SUPERFICIE | U20: PROYECTOS E INFRAESTUCTURA | V20: AYUDANTE TECNICO CIVIL | W20: TRUJILLO | X20: Caserio Las Delicias | Y20: OYUTUN | Z20: CHICLAYO | AA20: LAMBAYEQUE | AB20: 27 | AC20: UNIDAD MINERA | AD20: TRUJILLO
A21: 7 | B21: SAN ANDRES | C21: CENTRO MEDICO | D21: AFILIADO | F21: DNI | G21: 48482684 | H21: REYES | I21: HERNANDEZ | J21: YEFRY ALFONSO | K21: =CONCATENATE(H21," ",I21," ",J21) -> REYES HERNANDEZ YEFRY ALFONSO | L21: MASCULINO | M21: 32720 | N21: 915228568 | O21: RENUNCIO | P21: MINERA AURIFERA RETAMAS S.A. | Q21: SAN ANDRES | R21: GRUPO CREDCO EMPRESA DE INGENIERIA, ARQUITECTURA Y CONSTRUCCION S.A.C. | S21: 20601242657 | T21: SUPERFICIE | U21: PROYECTOS E INFRAESTUCTURA | V21: AYUDANTE TECNICO CIVIL | W21: TRUJILLO | X21: Calle Francia 40 | Y21: CHICLIN | Z21: ASCOPE | AA21: LA LIBERTAD | AB21: 31 | AC21: UNIDAD MINERA | AD21: TRUJILLO
A22: 10 | B22: SAN ANDRES | C22: CENTRO MEDICO | D22: GC0000050 | F22: DNI | G22: 47676739 | H22: SANCHEZ | I22: MENDOZA | J22: ALEX | K22: =CONCATENATE(H22," ",I22," ",J22) -> SANCHEZ MENDOZA ALEX | L22: MASCULINO | M22: 34010 | O22: RENUNCIO | P22: MINERA AURIFERA RETAMAS S.A. | Q22: SAN ANDRES | R22: GRUPO CREDCO EMPRESA DE INGENIERIA, ARQUITECTURA Y CONSTRUCCION S.A.C. | S22: 20601242662 | T22: SUPERFICIE | U22: PROYECTOS E INFRAESTUCTURA | V22: OFICIAL CIVIL | W22: CAJAMARCA | X22: Caserio Moyococha | Y22: CAJAMARCA | Z22: CAJAMARCA | AA22: CAJAMARCA | AB22: 27 | AC22: UNIDAD MINERA | AD22: TRUJILLO
A23: 12 | B23: SAN ANDRES | C23: CENTRO MEDICO | D23: GC0000047 | F23: DNI | G23: 41917682 | H23: RUIZ | I23: QUEZADA | J23: MIGUEL ANGEL | K23: =CONCATENATE(H23," ",I23," ",J23) -> RUIZ QUEZADA MIGUEL ANGEL | L23: MASCULINO | M23: 30249 | N23: 941490348 | O23: RENUNCIO | P23: MINERA AURIFERA RETAMAS S.A. | Q23: SAN ANDRES | R23: GRUPO CREDCO EMPRESA DE INGENIERIA, ARQUITECTURA Y CONSTRUCCION S.A.C. | S23: 20601242662 | T23: SUPERFICIE | U23: PROYECTOS E INFRAESTUCTURA | V23: PEON CIVIL | W23: CHICAMA | X23: AA.HH 11 de Febrero, Mz. C Lt. 24 | Y23: CHICAMA | Z23: ASCOPE | AA23: LA LIBERTAD | AB23: 48 | AC23: UNIDAD MINERA | AD23: TRUJILLO
A24: 13 | B24: SAN ANDRES | C24: CENTRO MEDICO | D24: GC0000046 | F24: DNI | G24: 74241245 | H24: RODRIGUEZ | I24: AVILA | J24: CARLOS MANUEL | K24: =CONCATENATE(H24," ",I24," ",J24) -> RODRIGUEZ AVILA CARLOS MANUEL | L24: MASCULINO | M24: 35498 | O24: RENUNCIO | P24: MINERA AURIFERA RETAMAS S.A. | Q24: SAN ANDRES | R24: GRUPO CREDCO EMPRESA DE INGENIERIA, ARQUITECTURA Y CONSTRUCCION S.A.C. | S24: 20601242662 | T24: SUPERFICIE | U24: PROYECTOS E INFRAESTUCTURA | V24: PEON CIVIL | W24: CHICAMA | X24: AA.HH La Pascona Mz. B lt. 03 | Y24: CHICAMA | Z24: ASCOPE | AA24: LA LIBERTAD | AB24: 24 | AC24: UNIDAD MINERA | AD24: TRUJILLO
A25: 14 | B25: SAN ANDRES | C25: CENTRO MEDICO | D25: GC0000045 | F25: DNI | G25: 45772855 | H25: SORIA | I25: HUAMAN | J25: AMERICO | K25: =CONCATENATE(H25," ",I25," ",J25) -> SORIA HUAMAN AMERICO | L25: MASCULINO | M25: 31922 | N25: 987790971 | O25: RENUNCIO | P25: MINERA AURIFERA RETAMAS S.A. | Q25: SAN ANDRES | R25: GRUPO CREDCO EMPRESA DE INGENIERIA, ARQUITECTURA Y CONSTRUCCION S.A.C. | S25: 20601242662 | T25: SUPERFICIE | U25: PROYECTOS E INFRAESTUCTURA | V25: OFICIAL CIVIL | W25: CAJAMARCA | X25: Cruze de Diego Ferrer y Petateros | Y25: CAJAMARCA | Z25: CAJAMARCA | AA25: CAJAMARCA | AB25: 43 | AC25: UNIDAD MINERA | AD25: TRUJILLO
A26: 15 | B26: SAN ANDRES | C26: CENTRO MEDICO | D26: GC0000043 | F26: DNI | G26: 77680655 | H26: MENDEZ | I26: LLAJARUNA | J26: JOSE ARMANDO | K26: =CONCATENATE(H26," ",I26," ",J26) -> MENDEZ LLAJARUNA JOSE ARMANDO | L26: MASCULINO | M26: 36407 | O26: RENUNCIO | P26: MINERA AURIFERA RETAMAS S.A. | Q26: SAN ANDRES | R26: GRUPO CREDCO EMPRESA DE INGENIERIA, ARQUITECTURA Y CONSTRUCCION S.A.C. | S26: 20601242662 | T26: SUPERFICIE | U26: PROYECTOS E INFRAESTUCTURA | V26: PEON CIVIL | W26: LA LIBERTAD | X26: Calle Ricardo Palma AA. HH. 11 de febrero Mz. C Lot. 7 | Y26: CHICAMA | Z26: ASCOPE | AA26: LA LIBERTAD | AB26: 21 | AC26: UNIDAD MINERA | AD26: TRUJILLO
A27: 39 | B27: SAN ANDRES | C27: CENTRO MEDICO | D27: GC0000051 | F27: DNI | G27: 71882744 | H27: LIMAY | I27: VALIENTE | J27: GENARO | K27: =CONCATENATE(H27," ",I27," ",J27) -> LIMAY VALIENTE GENARO | L27: MASCULINO | M27: 32621 | N27: 969311259 | O27: RENUNCIO | P27: MINERA AURIFERA RETAMAS S.A. | Q27: SAN ANDRES | R27: GRUPO CREDCO EMPRESA DE INGENIERIA, ARQUITECTURA Y CONSTRUCCION S.A.C. | S27: 20601242657 | T27: SUPERFICIE | U27: PROYECTOS E INFRAESTUCTURA | V27: AYUDANTE VIGIA | W27: CAJAMARCA | X27: Lluscapampa El Granero | Y27: CAJAMARCA | Z27: CAJAMARCA | AA27: CAJAMARCA | AB27: 23 | AC27: UNIDAD MINERA | AD27: TRUJILLO
A28: 40 | B28: SAN ANDRES | C28: CENTRO MEDICO | D28: GC0000022 | F28: DNI | G28: 47833170 | H28: HERAS | I28: MINCHAN | J28: JOSE WILSON | K28: =CONCATENATE(H28," ",I28," ",J28) -> HERAS MINCHAN JOSE WILSON | L28: MASCULINO | M28: 34171 | N28: 975443991 | O28: RENUNCIO | P28: MINERA AURIFERA RETAMAS S.A. | Q28: SAN ANDRES | R28: GRUPO CREDCO EMPRESA DE INGENIERIA, ARQUITECTURA Y CONSTRUCCION S.A.C. | S28: 20601242657 | T28: SUPERFICIE | U28: PROYECTOS E INFRAESTUCTURA | V28: AYUDANTE VIGIA | W28: CAJAMARCA | X28: Huambocancha baja | Y28: CAJAMARCA | Z28: CAJAMARCA | AA28: CAJAMARCA | AB28: 27 | AC28: UNIDAD MINERA | AD28: TRUJILLO
A29: 41 | B29: SAN ANDRES | C29: CENTRO MEDICO | D29: GC0000026 | F29: DNI | G29: 72713905 | H29: CUEVA | I29: CASTREJON | J29: LUCAS | K29: =CONCATENATE(H29," ",I29," ",J29) -> CUEVA CASTREJON LUCAS | L29: MASCULINO | M29: 34657 | O29: RENUNCIO | P29: MINERA AURIFERA RETAMAS S.A. | Q29: SAN ANDRES | R29: GRUPO CREDCO EMPRESA DE INGENIERIA, ARQUITECTURA Y CONSTRUCCION S.A.C. | S29: 20601242658 | T29: SUPERFICIE | U29: PROYECTOS E INFRAESTUCTURA | V29: AYUDANTE VIGIA | W29: CAJAMARCA | X29: Las Diamelas s/n Urb. El Molino | Y29: CAJAMARCA | Z29: CAJAMARCA | AA29: CAJAMARCA | AB29: 26 | AC29: UNIDAD MINERA | AD29: TRUJILLO
A30: 42 | B30: SAN ANDRES | C30: CENTRO MEDICO | D30: GC0000012 | F30: DNI | G30: 41193394 | H30: LLOVERA | I30: MICHAN | J30: SAMUEL SEGUNDO | K30: =CONCATENATE(H30," ",I30," ",J30) -> LLOVERA MICHAN SAMUEL SEGUNDO | L30: MASCULINO | M30: 15/09/1980 | N30: 976971622 | O30: RENUNCIO | P30: MINERA AURIFERA RETAMAS S.A. | Q30: SAN ANDRES | R30: GRUPO CREDCO EMPRESA DE INGENIERIA, ARQUITECTURA Y CONSTRUCCION S.A.C. | S30: 20601242657 | T30: SUPERFICIE | U30: PROYECTOS E INFRAESTUCTURA | V30: CONDUCTOR DE CAMIONETA | W30: CAJAMARCA | X30: Jr. Mariategui 197 | Y30: CAJAMARCA | Z30: CAJAMARCA | AA30: CAJAMARCA | AB30: 40 | AC30: UNIDAD MINERA | AD30: TRUJILLO
A31: 44 | B31: SAN ANDRES | C31: CENTRO MEDICO | D31: GC0000042 | F31: DNI | G31: 26712445 | H31: FERNANDEZ | I31: CANAN | J31: FERNANDO MANUEL | K31: FERNANDEZ CANAN FERNANDO MANUEL | L31: MASCULINO | M31: 08/09/1990 | N31: 966418312/992358966 | O31: RENUNCIO | P31: MINERA AURIFERA RETAMAS S.A. | Q31: SAN ANDRES | R31: GRUPO CREDCO EMPRESA DE INGENIERIA, ARQUITECTURA Y CONSTRUCCION S.A.C. | S31: 20601242657 | T31: SUPERFICIE | U31: PROYECTOS E INFRAESTUCTURA | V31: CONDUCTOR DE CAMION 2 | W31: CAJAMARCA | X31: Cajamarca la paccha sin número | Y31: CAJAMARCA | Z31: CAJAMARCA | AA31: CAJAMARCA | AB31: 47 | AC31: UNIDAD MINERA | AD31: TRUJILLO
A32: 46 | B32: SAN ANDRES | C32: CENTRO MEDICO | D32: GC0000055 | F32: DNI | G32: 75398571 | H32: CANALES | I32: ULLOA | J32: ITALO ROMARIO | K32: CANALES ULLOA ITALO ROMARIO | L32: MASCULINO | M32: 22/03/1997 | N32: 970113210 | O32: RENUNCIO | P32: MINERA AURIFERA RETAMAS S.A. | Q32: SAN ANDRES | R32: GRUPO CREDCO EMPRESA DE INGENIERIA, ARQUITECTURA Y CONSTRUCCION S.A.C. | S32: 20601242657 | T32: SUPERFICIE | U32: PROYECTOS E INFRAESTUCTURA | V32: PEON CIVIL | W32: LA LIBERTAD | X32: Progreso N° 25 | Y32: CHICLIN | Z32: ASCOPE | AA32: LA LIBERTAD | AB32: 24 | AC32: UNIDAD MINERA | AD32: TRUJILLO
A33: 47 | B33: SAN ANDRES | C33: CENTRO MEDICO | D33: GC0000056 | F33: DNI | G33: 45635754 | H33: SAENZ | I33: CASTILLO | J33: ALEXIS ALFREDO | K33: SAENZ CASTILLO ALEXIS ALFREDO | L33: MASCULINO | M33: 29/04/1987 | O33: RENUNCIO | P33: MINERA AURIFERA RETAMAS S.A. | Q33: SAN ANDRES | R33: GRUPO CREDCO EMPRESA DE INGENIERIA, ARQUITECTURA Y CONSTRUCCION S.A.C. | S33: 20601242657 | T33: SUPERFICIE | U33: PROYECTOS E INFRAESTUCTURA | V33: PEON CIVIL | W33: LA LIBERTAD | X33: Calle Bolognesi 5 Sector-Sintuco | Y33: CHOCOPE | Z33: ASCOPE | AA33: LA LIBERTAD | AB33: 34 | AC33: UNIDAD MINERA | AD33: TRUJILLO
A34: 48 | B34: SAN ANDRES | C34: CENTRO MEDICO | D34: GC0000054 | F34: DNI | G34: 71770675 | H34: SALAZAR | I34: CONDOR | J34: JUAN CARLOS | K34: SALAZAR CONDOR JUAN CARLOS | L34: MASCULINO | M34: 11/06/1999 | O34: RENUNCIO | P34: MINERA AURIFERA RETAMAS S.A. | Q34: SAN ANDRES | R34: GRUPO CREDCO EMPRESA DE INGENIERIA, ARQUITECTURA Y CONSTRUCCION S.A.C. | S34: 20601242657 | T34: SUPERFICIE | U34: PROYECTOS E INFRAESTUCTURA | V34: PEON CIVIL | W34: CAJAMARCA | X34: Caserio Shudal | Y34: CAJAMARCA | Z34: CAJAMARCA | AA34: CAJAMARCA | AB34: 22 | AC34: UNIDAD MINERA | AD34: TRUJILLO
A35: 49 | B35: SAN ANDRES | C35: CENTRO MEDICO | D35: AFILIADO | F35: DNI | G35: 76649315 | H35: CUEVA | I35: HUAMAN | J35: WALTER | K35: CUEVA HUAMAN WALTER | L35: MASCULINO | M35: 08/04/1998 | O35: RENUNCIO | P35: MINERA AURIFERA RETAMAS S.A. | Q35: SAN ANDRES | R35: GRUPO CREDCO EMPRESA DE INGENIERIA, ARQUITECTURA Y CONSTRUCCION S.A.C. | S35: 20601242657 | T35: SUPERFICIE | U35: PROYECTOS E INFRAESTUCTURA | V35: PEON CIVIL | W35: CAJAMARCA | X35: Caserio Porconcillo Alto | Y35: CAJAMARCA | Z35: CAJAMARCA | AA35: CAJAMARCA | AB35: 34 | AC35: UNIDAD MINERA | AD35: TRUJILLO
A36: 50 | B36: SAN ANDRES | C36: CENTRO MEDICO | D36: AFILIADO | F36: DNI | G36: 71401277 | H36: TAPIA | I36: BOÑON | J36: BILLY GERSON | K36: TAPIA GOÑON BILLY GERSON | L36: MASCULINO | M36: 23/12/2000 | O36: RENUNCIO | P36: MINERA AURIFERA RETAMAS S.A. | Q36: SAN ANDRES | R36: GRUPO CREDCO EMPRESA DE INGENIERIA, ARQUITECTURA Y CONSTRUCCION S.A.C. | S36: 20601242657 | T36: SUPERFICIE | U36: PROYECTOS E INFRAESTUCTURA | V36: PEON CIVIL | W36: CAJAMARCA | X36: Jr. La Victoria N° 102 | Y36: CAJAMARCA | Z36: CAJAMARCA | AA36: CAJAMARCA | AB36: 21 | AC36: UNIDAD MINERA | AD36: TRUJILLO
A37: 51 | B37: SAN ANDRES | C37: CENTRO MEDICO | D37: AFILIADO | F37: DNI | G37: 48479682 | H37: DUCOS | I37: DE LA CRUZ | J37: VENJAMIN | K37: DUCOS DE LA CRUZ VENJAMIN | L37: MASCULINO | M37: 20/01/1995 | O37: RENUNCIO | P37: MINERA AURIFERA RETAMAS S.A. | Q37: SAN ANDRES | R37: GRUPO CREDCO EMPRESA DE INGENIERIA, ARQUITECTURA Y CONSTRUCCION S.A.C. | S37: 20601242657 | T37: SUPERFICIE | U37: PROYECTOS E INFRAESTUCTURA | V37: PEON CIVIL | W37: CAJAMARCA | X37: Centro Poblado Porcon Bajo | Y37: CAJAMARCA | Z37: CAJAMARCA | AA37: CAJAMARCA | AB37: 26 | AC37: UNIDAD MINERA | AD37: TRUJILLO
A38: 52 | B38: SAN ANDRES | C38: CENTRO MEDICO | D38: AFILIADO | F38: DNI | G38: 63410203 | H38: VILLAREAL | I38: SOLORZANO | J38: TADASHY JUAN | K38: VILLAREAL SOLORZANO TADASHY | L38: MASCULINO | M38: 20/05/2000 | O38: RENUNCIO | P38: MINERA AURIFERA RETAMAS S.A. | Q38: SAN ANDRES | R38: GRUPO CREDCO EMPRESA DE INGENIERIA, ARQUITECTURA Y CONSTRUCCION S.A.C. | S38: 20601242657 | T38: SUPERFICIE | U38: PROYECTOS E INFRAESTUCTURA | V38: PEON CIVIL | W38: LA LIBERTAD | X38: Lotizacion Chiclin Calle España N° 16 | Y38: TRUJILLO | Z38: TRUJILLO | AA38: LA LIBERTAD | AB38: 21 | AC38: UNIDAD MINERA | AD38: TRUJILLO
A39: 55 | B39: SAN ANDRES | C39: CENTRO MEDICO | D39: GC0000064 | F39: DNI | G39: 46975532 | H39: VALDIVIA | I39: HUAMAN | J39: ROBERTO | K39: VALDIVIA HUAMAN ROBERTO | L39: MASCULINO | M39: 08/12/1991 | N39: 976192265 | O39: RENUNCIO | P39: MINERA AURIFERA RETAMAS S.A. | Q39: SAN ANDRES | R39: GRUPO CREDCO EMPRESA DE INGENIERIA, ARQUITECTURA Y CONSTRUCCION S.A.C. | S39: 20601242657 | T39: SUPERFICIE | U39: PROYECTOS E INFRAESTUCTURA | V39: OPERARIO CARPINTERO | W39: CAJAMARCA | X39: Caserio Plan Porcillo | Y39: CAJAMARCA | Z39: CAJAMARCA | AA39: CAJAMARCA | AB39: 29 | AC39: UNIDAD MINERA | AD39: TRUJILLO
A40: 58 | B40: SAN ANDRES | C40: CENTRO MEDICO | D40: GC0000068 | F40: DNI | G40: 72414296 | H40: QUINTANA | I40: PALMA | J40: MILVER YOEL | K40: QUINTANA PALMA MILVAR YOEL | L40: MASCULINO | M40: 13/05/2001 | N40: 954790315 | O40: RENUNCIO | P40: MINERA AURIFERA RETAMAS S.A. | Q40: SAN ANDRES | R40: GRUPO CREDCO EMPRESA DE INGENIERIA, ARQUITECTURA Y CONSTRUCCION S.A.C. | S40: 20601242657 | T40: SUPERFICIE | U40: PROYECTOS E INFRAESTUCTURA | V40: PEON CIVIL | W40: CAJAMARCA | X40: Centro Poblado Santa Barbara | Y40: CAJAMARCA | Z40: CAJAMARCA | AA40: CAJAMARCA | AB40: 20 | AC40: UNIDAD MINERA | AD40: TRUJILLO
A41: 59 | B41: SAN ANDRES | C41: CENTRO MEDICO | D41: GC0000067 | F41: DNI | G41: 70845004 | H41: GUARNIZ | I41: MARIÑO | J41: ALBERTO LEONEL | K41: GURANIZ MARIÑOS ALBERTO LEONEL | L41: MASCULINO | M41: 36326 | N41: 912855776 | O41: RENUNCIO | P41: MINERA AURIFERA RETAMAS S.A. | Q41: SAN ANDRES | R41: GRUPO CREDCO EMPRESA DE INGENIERIA, ARQUITECTURA Y CONSTRUCCION S.A.C. | S41: 20601242657 | T41: SUPERFICIE | U41: PROYECTOS E INFRAESTUCTURA | V41: PEON CIVIL | W41: LA LIBERTAD | X41: AA.HH. Alan Garcia Mz.Glot. 3 | Y41: CHICAMA | Z41: ASCOPE | AA41: LA LIBERTAD | AB41: 22 | AC41: UNIDAD MINERA | AD41: TRUJILLO
A42: 60 | B42: SAN ANDRES | C42: CENTRO MEDICO | D42: GC0000069 | F42: DNI | G42: 73363131 | H42: INFANTE | I42: GASTOLOMENDO | J42: RAVID | K42: INFANTE GASTOLOMENDO RAVID | L42: MASCULINO | M42: 15/05/1995 | N42: 974550672 | O42: RENUNCIO | P42: MINERA AURIFERA RETAMAS S.A. | Q42: SAN ANDRES | R42: GRUPO CREDCO EMPRESA DE INGENIERIA, ARQUITECTURA Y CONSTRUCCION S.A.C. | S42: 20601242657 | T42: SUPERFICIE | U42: PROYECTOS E INFRAESTUCTURA | V42: PEON CIVIL | W42: CAJAMARCA | X42: Centro Polbladop Porcon Alto | Y42: CAJAMARCA | Z42: CAJAMARCA | AA42: CAJAMARCA | AB42: 26 | AC42: UNIDAD MINERA | AD42: TRUJILLO
...

Sheet Hoja2
H1: N | I1: D | J1: M
H2: RABANAL SOTELO CARLOS DANIEL | I2: 7 | J2: 1
H3: ARRIBASPLATA ARRIBASPLATA YEISON ANTONI | I3: 13 | J3: 1
H4: CUEVA GARCIA JOSE GENARO | I4: 25 | J4: 1
E5: ANTICONA ANTICONA HEBER EFRAIN | H5: DELAO TORRES BRUNO | I5: 25 | J5: 1
E6: HUAYLLA LARREA ALVARO JOSÉ | H6: DELAO TORRES NELSON | I6: 5 | J6: 1
E7: CAMPOS FLORES ANTONIO | H7: VENEGAS RAMOS ENRIQUE HERMIS | I7: 23 | J7: 1
E8: LINARES HUAMAN UGO BENITO | H8: CHUNQUE PINEDO ALEXANDER | I8: 25 | J8: 2
E9: SANCHEZ MOSQUEIRA WALTER | H9: CAHUANA CHUQUIMANGO EDILBERTO | I9: 3 | J9: 2
E10: POMPA CUEVA NELSON ELVIS | H10: TISNADO ARRESTEGUI GERSON YADER | I10: 1 | J10: 2
E11: PESCORÁN CAMPOS MANUEL DAVID | H11: CUEVA TINGAL EDWIN | I11: 7 | J11: 2
E12: MISAHUAMAN BARDALES FRANKLIN | H12: JARA DE LA CRUZ BENAVIDES | I12: 3 | J12: 2
E13: DURAN PINEDO ELI | H13: LINARES RAMIREZ WILLIAM ALI | I13: 20 | J13: 2
H14: ROJAS MENDOZA JUNIOR JEORDI | I14: 10 | J14: 3
H15: ANTICONA ANTICONA HEBER EFRAIN | I15: 15 | J15: 4
H16: VILCA CONDOR INELSON | I16: 20 | J16: 4
H17: CUEVA HUANGAL ABDIAS | I17: 6 | J17: 4
H18: MIRANDA GALLARDO SEGUNDO EDUARDO | I18: 26 | J18: 4
H19: HUAYLLA LARREA ALVARO JOSÉ | I19: 4 | J19: 5
H20: CAMPOS FLORES ANTONIO | I20: 10 | J20: 5
H21: LINARES HUAMAN UGO BENITO | I21: 30 | J21: 5
H22: RAMIREZ POMPA JORGE LUIS ANTONIO | I22: 18 | J22: 5
H23: TERAN REVILLA NORBERTO | I23: 6 | J23: 6
H24: BURGOS JAYASI JORGE | I24: 13 | J24: 6
H25: ADRIANO CERVANTES DANIEL | I25: 20 | J25: 6
... H51: CARRASCO CHAVEZ CESAR | I51: 4 | J51: 12

Sheet Hoja1
J5: n | K5: f
J6: ADRIANO CERVANTES DANIEL | K6: OCUPADO
J7: ANTICONA ANTICONA HEBER EFRAIN | K7: OCUPADO
J8: ARIAS ARCE WILMER | K8: LIBRE
J9: ARRIBASPLATA ARRIBASPLATA YEISON ANTONI | K9: OCUPADO
C10: APELLIDOS Y NOMBRES | D10: DNI | E10: CARGO | F10: MOTIVO | G10: FECHA DE PROGRAMACIÓN | H10: HORA | J10: BURGOS JAYASI JORGE | K10: OCUPADO
C11: ='PERSONAL ACTIVO'!#REF! -> #REF! | D11: ='PERSONAL ACTIVO'!#REF! -> #REF! | E11: OFICIAL CIVIL | F11: Término de contrato | G11: 45656 | H11: 0.29166667 | J11: CAHUANA CHUQUIMANGO EDILBERTO | K11: LIBRE
J12: CAMPOS FLORES ANTONIO | K12: OCUPADO
C13: APELLIDOS Y NOMBRES | D13: DNI | E13: CARGO | F13: CÓDIGO DE FOTOCHEK | G13: FECHA DE PROGRAMACIÓN | J13: CARHUAPOMA VARGAS OSWALDO | K13: LIBRE
C14: CUEVA GARCIA JOSE GENARO | D14: 72307618 | E14: AYUDANTE DE OBRAS CIVILES | F14: GC0000242 | G14: 45658 | J14: CARRANZA MISAHUAMAN RONAL MIKI | K14: LIBRE
C15: DELAO TORRES BRUNO | D15: 47697810 | E15: AYUDANTE DE OBRAS CIVILES | F15: GC0000241 | G15: 45658 | J15: CARRASCO CHAVEZ CESAR | K15: OCUPADO
C16: DELAO TORRES NELSON | D16: 75141452 | E16: AYUDANTE DE OBRAS CIVILES | F16: GC0000240 | G16: 45658 | J16: CARRILLO ZAPATA CARLOS EDUARDO | K16: LIBRE
J17: CHAVEZ NORIEGA GUSMAN | K17: OCUPADO
J18: CHUNQUE PINEDO ALEXANDER | K18: LIBRE
J19: CUEVA GARCIA JOSE GENARO | K19: LIBRE
J20: CUEVA HUANGAL, ABDIAS | K20: OCUPADO
J21: CUEVA TINGAL EDWIN | K21: OCUPADO
J22: DELAO TORRES BRUNO | K22: OCUPADO
J23: DELAO TORRES NELSON | K23: OCUPADO
J24: DURAN PINEDO ELI | K24: OCUPADO
J25: HORNA BURGOS HUGO JORDAN | K25: OCUPADO
J26: JARA DE LA CRUZ BENAVIDES | K26: LIBRE
J27: LINARES BLONDET LUIS II | K27: OCUPADO
J28: LINARES HUAMAN UGO BENITO | K28: OCUPADO
... J52: VILCA CONDOR INELSON | K52: LIBRE

Sheet Hoja3
B6: TARRILLO COLLANTES EDWIN ALEXANDER
B8: HUAYLLA LARREA ALVARO JOSÉ
B10: CHUNQUE PINEDO ALEXANDER
B11: HORNA BURGOS HUGO JORDAN
B12: CARRANZA MISAHUAMAN RONAL MIKI
B13: TERAN REVILLA NORBERTO
B14: ANTICONA ANTICONA HEBER EFRAIN
B15: CAHUANA CHUQUIMANGO EDILBERTO
B17: MISAHUAMAN BARDALES FRANKLIN
B18: POMPA CUEVA NELSON ELVIS
B21: ROJAS PEÑA ROSMA ROEL
B22: BURGOS JAYASI JORGE
... B44: VENEGAS RAMOS ENRIQUE HERMIS
